Workbook

Sheet DAF general overview (DAF map)

Sheet Assesment outcomes
Q1: The guidance on completing the form are available in our GitHub repository
B2: Домен | D2: Model | E2: Domains | F2: Practices requirements | G2: Subdomain ID | H2: 0. Uninitiated | I2: 1. Beginners | J2: 2. Intermediate | K2: 3. Advanced | L2: 4. Experts | M2: % of practices implemented | N2: % of practices implemented for the subdomain | O2: % of practices implemented total | Q2: DAF maturity pyramid level | S2: % of Compliance with the Maturity Level (DAF maturity pyramid) | T2: Overall DAF maturity level for the organization | V2: Transition threshold for each DAF pyramid level | Y2: 0.8
B3: Технологии | D3: Technologies | E3: Control of artifacts, dependencies, and images | F3: Management and control of external component usage | G3: T-ADI-DEP | H3: =IF('Practices and Requirements'!E4="False","Not implemented","Implemented") -> Implemented | I3: ='Practices and Requirements'!G5 -> 0 | J3: ='Practices and Requirements'!G10 -> 0 | K3: ='Practices and Requirements'!G12 -> 0 | L3: ='Practices and Requirements'!G15 -> 0 | M3: =SUM(I3:L3)/4 -> 0 | N3: =AVERAGE(M3:M4) -> 0 | O3: =AVERAGE(M3:M42) -> 0 | Q3: 0 | R3: Chaos | S3: ='DAF maturity pyramid'!C87 -> 0 | T3: =Y10 -> 0
F4: Management and control of application development artifacts | G4: T-ADI-ART | H4: =IF('Practices and Requirements'!E17="False","Not implemented","Implemented") -> Implemented | I4: ='Practices and Requirements'!G18 -> 0 | J4: ='Practices and Requirements'!G23 -> 0 | K4: ='Practices and Requirements'!G25 -> 0 | L4: ='Practices and Requirements'!G27 -> 0 | M4: =SUM(I4:L4)/4 -> 0 | Q4: 1 | R4: Minimal | S4: ='DAF maturity pyramid'!D87 -> 0 | V4: Under the DAF methodology, DAF maturity pyramid level is only assigned when two mandatory conditions are met: - At least 80 % of the practices for that level have been completed; - All preceding maturity levels have been completed to a minimum of 80% Calculation notes: 1. First check whether each of the levels “Chaos” (level 0) and “Minimal” (level 1) have been completed at ≥ 80% (cell R37). If both are completed, assign level 1; if not, remain at level 0. 2. Next, check whether the “Basic” level is completed at ≥ 80%. If yes, assign level 2; if no, refer to cell R37. 3. Then check whether the “Enhanced” level is completed at ≥ 80%. If yes, assign level 3; if no, refer to cell R38. 4. Continue similarly for subsequent levels. | Y4: =IF(AND(S3>=Y2, S4>=Y2),1,0) -> 0
E5: Development environment security | F5: Developers workstations security | G5: T-DEV-COMP | H5: =IF('Practices and Requirements'!E33="False","Not implemented","Implemented") -> Implemented | I5: ='Practices and Requirements'!G34 -> 0 | J5: ='Practices and Requirements'!G36 -> 0 | M5: =SUM(I5:J5)/2 -> 0 | N5: =AVERAGE(M5:M10) -> 0 | Q5: 2 | R5: Basic | S5: ='DAF maturity pyramid'!E87 -> 0 | Y5: =IF(AND(Y4=1,S5>=Y2),2,Y4) -> 0
F6: Secrets management in DEV/TEST environments | G6: T-DEV-SM | H6: =IF('Practices and Requirements'!E37="False","Not implemented","Implemented") -> Implemented | I6: ='Practices and Requirements'!G38 -> 0 | J6: ='Practices and Requirements'!G40 -> 0 | K6: ='Practices and Requirements'!G42 -> 0 | L6: ='Practices and Requirements'!G44 -> 0 | M6: =SUM(I6:L6)/4 -> 0 | Q6: 3 | R6: Enhanced | S6: ='DAF maturity pyramid'!F87 -> 0 | Y6: =IF(AND(Y5=2,S6>=Y2),3,Y5) -> 0
F7: Build-environment security | G7: T-DEV-BLD | H7: =IF('Practices and Requirements'!E45="False","Not implemented","Implemented") -> Implemented | I7: ='Practices and Requirements'!G46 -> 0 | J7: ='Practices and Requirements'!G50 -> 0 | K7: ='Practices and Requirements'!G51 -> 0 | L7: ='Practices and Requirements'!G54 -> 0 | M7: =SUM(I7:L7)/4 -> 0 | Q7: 4 | R7: Advanced | S7: ='DAF maturity pyramid'!G87 -> 0 | Y7: =IF(AND(Y6=3,S7>=Y2),4,Y6) -> 0
F8: Source code management system (SCM) security | G8: T-DEV-SCM | H8: =IF('Practices and Requirements'!E55="False","Not implemented","Implemented") -> Implemented | I8: ='Practices and Requirements'!G56 -> 0 | J8: ='Practices and Requirements'!G63 -> 0 | K8: ='Practices and Requirements'!G69 -> 0 | L8: ='Practices and Requirements'!G73 -> 0 | M8: =SUM(I8:L8)/4 -> 0 | Q8: 5 | R8: Developed | S8: ='DAF maturity pyramid'!H87 -> 0 | Y8: =IF(AND(Y7=4,S8>=Y2),5,Y7) -> 0
F9: Source code change management and control | G9: T-DEV-SRC | H9: =IF('Practices and Requirements'!E76="False","Not implemented","Implemented") -> Implemented | I9: ='Practices and Requirements'!G77 -> 0 | J9: ='Practices and Requirements'!G82 -> 0 | K9: ='Practices and Requirements'!G88 -> 0 | L9: ='Practices and Requirements'!G94 -> 0 | M9: =SUM(I9:L9)/4 -> 0 | Q9: 6 | R9: Expert | S9: ='DAF maturity pyramid'!I87 -> 0 | Y9: =IF(AND(Y8=5,S9>=Y2),6,Y8) -> 0
F10: Build pipeline security | G10: T-DEV-CICD | H10: =IF('Practices and Requirements'!E95="False","Not implemented","Implemented") -> Implemented | I10: ='Practices and Requirements'!G96 -> 0 | J10: ='Practices and Requirements'!G101 -> 0 | K10: ='Practices and Requirements'!G103 -> 0 | L10: ='Practices and Requirements'!G104 -> 0 | M10: =SUM(I10:L10)/4 -> 0 | Q10: 7 | R10: Ultimate | S10: ='DAF maturity pyramid'!J87 -> 0 | Y10: =IF(AND(Y9=6,S10>=Y2),7,Y9) -> 0
E11: Tool-Based security defects detection and analysis | F11: Security assurance for vendor-developed software | G11: T-CODE-SPC | H11: =IF('Practices and Requirements'!E107="False","Not implemented","Implemented") -> Implemented | I11: ='Practices and Requirements'!G108 -> 0 | J11: ='Practices and Requirements'!G110 -> 0 | K11: ='Practices and Requirements'!G114 -> 0 | L11: ='Practices and Requirements'!G119 -> 0 | M11: =SUM(I11:L11)/4 -> 0 | N11: =AVERAGE(M11:M16) -> 0
F12: Static application security testing (SAST) | G12: T-CODE-SST | H12: =IF('Practices and Requirements'!E120="False","Not implemented","Implemented") -> Implemented | I12: ='Practices and Requirements'!G121 -> 0 | J12: ='Practices and Requirements'!G123 -> 0 | K12: ='Practices and Requirements'!G127 -> 0 | L12: ='Practices and Requirements'!G130 -> 0 | M12: =SUM(I12:L12)/4 -> 0
F13: Software Composition Analysis/Open Source Analysis (SCA/OSA) | G13: T-CODE-SC | H13: =IF('Practices and Requirements'!E131="False","Not implemented","Implemented") -> Implemented | I13: ='Practices and Requirements'!G132 -> 0 | J13: ='Practices and Requirements'!G135 -> 0 | K13: ='Practices and Requirements'!G140 -> 0 | L13: ='Practices and Requirements'!G144 -> 0 | M13: =SUM(I13:L13)/4 -> 0
F14: Image container security analysis | G14: T-CODE-IMG | H14: =IF('Practices and Requirements'!E145="False","Not implemented","Implemented") -> Implemented | I14: ='Practices and Requirements'!G146 -> 0 | J14: ='Practices and Requirements'!G149 -> 0 | K14: ='Practices and Requirements'!G152 -> 0 | L14: ='Practices and Requirements'!G153 -> 0 | M14: =SUM(I14:L14)/4 -> 0
F15: Secrets detection | G15: T-CODE-SECDN | H15: =IF('Practices and Requirements'!E155="False","Not implemented","Implemented") -> Implemented | I15: ='Practices and Requirements'!G156 -> 0 | J15: ='Practices and Requirements'!G160 -> 0 | K15: ='Practices and Requirements'!G163 -> 0 | L15: ='Practices and Requirements'!G166 -> 0 | M15: =SUM(I15:L15)/4 -> 0
F16: Dockerfiles analysis | G16: T-CODE-DOCKERFS | H16: =IF('Practices and Requirements'!E167="False","Not implemented","Implemented") -> Implemented | I16: ='Practices and Requirements'!G168 -> 0 | J16: ='Practices and Requirements'!G170 -> 0 | M16: =SUM(I16:J16)/2 -> 0
E17: Runtime application analysis (Pre-Prod environment) | F17: Dynamic Application Security testing (DAST) in PREPROD environment | G17: T-PREPROD-DAST | H17: =IF('Practices and Requirements'!E173="False","Not implemented","Implemented") -> Implemented | I17: ='Practices and Requirements'!G174 -> 0 | J17: ='Practices and Requirements'!G176 -> 0 | K17: ='Practices and Requirements'!G180 -> 0 | L17: ='Practices and Requirements'!G184 -> 0 | M17: =SUM(I17:L17)/4 -> 0 | N17: =AVERAGE(M17:M21) -> 0
F18: Pre-Release software penetration testing | G18: T-PREPROD-PENTEST | H18: =IF('Practices and Requirements'!E187="False","Not implemented","Implemented") -> Implemented | I18: ='Practices and Requirements'!G188 -> 0 | J18: ='Practices and Requirements'!G191 -> 0 | L18: ='Practices and Requirements'!G192 -> 0 | M18: =SUM(I18:L18)/3 -> 0
F19: Functional security testing | G19: T-PREPROD-SECTEST | H19: =IF('Practices and Requirements'!E193="False","Not implemented","Implemented") -> Implemented | I19: ='Practices and Requirements'!G194 -> 0 | J19: ='Practices and Requirements'!G195 -> 0 | K19: ='Practices and Requirements'!G197 -> 0 | M19: =SUM(I19:K19)/3 -> 0
F20: Manifests security management (k8s, terraform etc) | G20: T-PREPROD-MANSEC | H20: =IF('Practices and Requirements'!E210="False","Not implemented","Implemented") -> Implemented | I20: ='Practices and Requirements'!G211 -> 0 | J20: ='Practices and Requirements'!G212 -> 0 | M20: =SUM(I20:J20)/2 -> 0
F21: Vulnerability management (PREPROD Infrastructure) | G21: T-PREPROD-VULN | H21: =IF('Practices and Requirements'!E198="False","Not implemented","Implemented") -> Implemented | I21: ='Practices and Requirements'!G199 -> 0 | J21: ='Practices and Requirements'!G201 -> 0 | K21: ='Practices and Requirements'!G204 -> 0 | L21: ='Practices and Requirements'!G208 -> 0 | M21: =SUM(I21:L21)/4 -> 0
E22: Applications & infrastructure security (Runtime in the production environment) | F22: Secrets management in PROD environment | G22: T-PROD-SM | H22: =IF('Practices and Requirements'!E215="False","Not implemented","Implemented") -> Implemented | I22: ='Practices and Requirements'!G216 -> 0 | J22: ='Practices and Requirements'!G218 -> 0 | K22: ='Practices and Requirements'!G220 -> 0 | L22: ='Practices and Requirements'!G223 -> 0 | M22: =SUM(I22:L22)/4 -> 0 | N22: =AVERAGE(M22:M29) -> 0
F23: Dynamic Application Security Testing (DAST) in PROD environment | G23: T-PROD-DAST | H23: =IF('Practices and Requirements'!E234="False","Not implemented","Implemented") -> Implemented | I23: ='Practices and Requirements'!G235 -> 0 | J23: ='Practices and Requirements'!G238 -> 0 | K23: ='Practices and Requirements'!G242 -> 0 | L23: ='Practices and Requirements'!G246 -> 0 | M23: =SUM(I23:L23)/4 -> 0
F24: Penetration testing in PROD environment | G24: T-PROD-PENTEST | H24: =IF('Practices and Requirements'!E226="False","Not implemented","Implemented") -> Implemented | I24: ='Practices and Requirements'!G227 -> 0 | J24: ='Practices and Requirements'!G230 -> 0 | K24: ='Practices and Requirements'!G231 -> 0 | L24: ='Practices and Requirements'!G232 -> 0 | M24: =SUM(I24:L24)/4 -> 0
F25: Management of Infrastructure changes and access permissions | G25: T-PROD-ACCESS | H25: =IF('Practices and Requirements'!E249="False","Not implemented","Implemented") -> Implemented | I25: ='Practices and Requirements'!G250 -> 0 | J25: ='Practices and Requirements'!G255 -> 0 | K25: ='Practices and Requirements'!G257 -> 0 | L25: ='Practices and Requirements'!G258 -> 0 | M25: =SUM(I25:L25)/4 -> 0
F26: Network traffic monitoring and control (L4–L7) | G26: T-PROD-NETWORK | H26: =IF('Practices and Requirements'!E259="False","Not implemented","Implemented") -> Implemented | I26: ='Practices and Requirements'!G260 -> 0 | J26: ='Practices and Requirements'!G262 -> 0 | K26: ='Practices and Requirements'!G264 -> 0 | M26: =SUM(I26:K26)/3 -> 0
F27: Runtime environment monitoring and control | G27: T-PROD-RUN | H27: =IF('Practices and Requirements'!E265="False","Not implemented","Implemented") -> Implemented | I27: ='Practices and Requirements'!G266 -> 0 | J27: ='Practices and Requirements'!G267 -> 0 | K27: ='Practices and Requirements'!G268 -> 0 | M27: =SUM(I27:K27)/3 -> 0
F28: Vulnerability management (PROD Infrastructure) | G28: T-PROD-VULN | H28: =IF('Practices and Requirements'!E269="False","Not implemented","Implemented") -> Implemented | I28: ='Practices and Requirements'!G270 -> 0 | J28: ='Practices and Requirements'!G272 -> 0 | K28: ='Practices and Requirements'!G275 -> 0 | L28: ='Practices and Requirements'!G279 -> 0 | M28: =SUM(I28:L28)/4 -> 0
F29: Security events monitoring and management | G29: T-PROD-EVENTS | H29: =IF('Practices and Requirements'!E281="False","Not implemented","Implemented") -> Implemented | J29: ='Practices and Requirements'!G282 -> 0 | K29: ='Practices and Requirements'!G283 -> 0 | M29: =SUM(J29:K29)/2 -> 0
B30: Процессы | D30: Processes | E30: Training and knowledge management | F30: DevSecOps secure development training | G30: P-EDU-AWR | H30: =IF('Practices and Requirements'!E286="False","Not implemented","Implemented") -> Implemented | I30: ='Practices and Requirements'!G287 -> 0 | J30: ='Practices and Requirements'!G289 -> 0 | K30: ='Practices and Requirements'!G293 -> 0 | L30: ='Practices and Requirements'!G295 -> 0 | M30: =SUM(I30:L30)/4 -> 0 | N30: =AVERAGE(M30:M31) -> 0
F31: DevSecOps knowledge base management | G31: P-EDU-KB | H31: =IF('Practices and Requirements'!E296="False","Not implemented","Implemented") -> Implemented | I31: ='Practices and Requirements'!G297 -> 0 | J31: ='Practices and Requirements'!G298 -> 0 | K31: ='Practices and Requirements'!G300 -> 0 | L31: ='Practices and Requirements'!G303 -> 0 | M31: =SUM(I31:L31)/4 -> 0
E32: Software security requirements management | F32: Software criticality assessment and threat modeling | G32: P-REQ-TM | H32: =IF('Practices and Requirements'!E307="False","Not implemented","Implemented") -> Implemented | I32: ='Practices and Requirements'!G308 -> 0 | J32: ='Practices and Requirements'!G311 -> 0 | K32: ='Practices and Requirements'!G314 -> 0 | L32: ='Practices and Requirements'!G317 -> 0 | M32: =SUM(I32:L32)/4 -> 0 | N32: =AVERAGE(M32:M36) -> 0
F33: Defining security requirements for applications under development | G33: P-REQ-RD | H33: =IF('Practices and Requirements'!E318="False","Not implemented","Implemented") -> Implemented | I33: ='Practices and Requirements'!G319 -> 0 | J33: ='Practices and Requirements'!G321 -> 0 | K33: ='Practices and Requirements'!G324 -> 0 | L33: ='Practices and Requirements'!G327 -> 0 | M33: =SUM(I33:L33)/4 -> 0
F34: Verification of compliance with security requirements | G34: P-REQ-CR | H34: =IF('Practices and Requirements'!E328="False","Not implemented","Implemented") -> Implemented | I34: ='Practices and Requirements'!G329 -> 0 | J34: ='Practices and Requirements'!G330 -> 0 | K34: ='Practices and Requirements'!G331 -> 0 | L34: ='Practices and Requirements'!G332 -> 0 | M34: =SUM(I34:L34)/4 -> 0
F35: Software security configuration standards | G35: P-REQ-STDR-App | H35: =IF('Practices and Requirements'!E333="False","Not implemented","Implemented") -> Implemented | I35: ='Practices and Requirements'!G334 -> 0 | J35: ='Practices and Requirements'!G336 -> 0 | K35: ='Practices and Requirements'!G337 -> 0 | L35: ='Practices and Requirements'!G339 -> 0 | M35: =SUM(I35:L35)/4 -> 0
F36: Infrastructure components security configuration management | G36: P-REQ-STDR-Infr | H36: =IF('Practices and Requirements'!E340="False","Not implemented","Implemented") -> Implemented | I36: ='Practices and Requirements'!G341 -> 0 | J36: ='Practices and Requirements'!G343 -> 0 | K36: ='Practices and Requirements'!G345 -> 0 | L36: ='Practices and Requirements'!G348 -> 0 | M36: =SUM(I36:L36)/4 -> 0
E37: Security defects management | F37: Security defects handling | G37: P-DEFECT-MNG | H37: =IF('Practices and Requirements'!E351="False","Not implemented","Implemented") -> Implemented | I37: ='Practices and Requirements'!G352 -> 0 | J37: ='Practices and Requirements'!G353 -> 0 | K37: ='Practices and Requirements'!G355 -> 0 | L37: ='Practices and Requirements'!G358 -> 0 | M37: =SUM(I37:L37)/4 -> 0 | N37: =AVERAGE(M37:M40) -> 0
F38: Security defects consolidation | G38: P-DEFECT-CNS | H38: =IF('Practices and Requirements'!E359="False","Not implemented","Implemented") -> Implemented | I38: ='Practices and Requirements'!G360 -> 0 | J38: ='Practices and Requirements'!G362 -> 0 | K38: ='Practices and Requirements'!G363 -> 0 | L38: ='Practices and Requirements'!G366 -> 0 | M38: =SUM(I38:L38)/4 -> 0
E39: DSO process effectiveness management | F39: Security metrics management | G39: P-MET-SET | H39: =IF('Practices and Requirements'!E369="False","Not implemented","Implemented") -> Implemented | J39: ='Practices and Requirements'!G370 -> 0 | K39: ='Practices and Requirements'!G372 -> 0 | M39: =SUM(J39:K39)/2 -> 0
F40: Security metrics compliance control | G40: P-MET-EX | H40: =IF('Practices and Requirements'!E374="False","Not implemented","Implemented") -> Implemented | J40: ='Practices and Requirements'!G375 -> 0 | K40: ='Practices and Requirements'!G377 -> 0 | L40: ='Practices and Requirements'!G380 -> 0 | M40: =SUM(J40:L40)/3 -> 0
...

Sheet Practices and Requirements
E1: The guidance on completing the form are available in our GitHub repository
B2: Subdomains | C2: ID | D2: Practices requirements | E2: Status | F2: Practice complexity level | G2: % of practices implemented per group | H2: % of practices implemented for subdomain | I2: DAF maturity pyramid level | J2: BSIMM v14 | K2: DSOMM | L2: OWASP SAMMv2 | M2: Auditor comments
B3: Domain "Control of artifacts, dependencies, and images"
B4: ='Assesment outcomes'!F3 -> Management and control of external component usage | C4: T-ADI-DEP-0-1 | D4: Dependency management in the source code is implemented in some form | E4: To be filled | F4: 0 | G4: =(COUNTIF(E4:E4,$F$406))/COUNTA(E4:E4) -> 0 | H4: =SUM(G5:G16)/4 -> 0 | I4: 0 | K4: 4 | L4: SB-B-1
C5: T-ADI-DEP-1-1 | D5: There are (formalized) unified rules that define whether certain dependencies can be used in the code. For example, there is an approved document and/or a knowledge base page describing the procedure for using dependencies in the code. | E5: To be filled | F5: 1 | G5: =(COUNTIF(E5:E9,$F$411)+(COUNTIF(E5:E9,$F$410)*0.5))/(COUNTA(E5:E9)-COUNTIF(E5:E9,$F$412)) -> 0 | I5: 2 | L5: SB-B-2
C6: T-ADI-DEP-1-2 | D6: Updates to the existing dependencies are performed manually. For example, when a new version of a library is required, you must manually download it and add it to the project. | E6: To be filled | I6: 2 | K6: 9 | L6: SB-B-2
C7: T-ADI-DEP-1-3 | D7: A documented and formalized response plan for information security incidents related to dependencies exists. | E7: To be filled | I7: 2 | J7: SR2.7
C8: T-ADI-DEP-1-4 | D8: Hardening (secure configuration) of configuration files for the open-source software (OSS) packages in use (e.g., nuget.config, .npmrc, pip.conf, pom.xml, etc.) is performed. | E8: To be filled | I8: 2 | K8: 83 91 56 | L8: EM-A-1
C9: T-ADI-DEP-1-5 | D9: Dependencies with the “latest” tag are not used. | E9: To be filled | I9: 2 | L9: SA-B-1
C10: T-ADI-DEP-2-1 | D10: Developers obtain and use OSS components exclusively through standardized (formalized and approved) methods. | E10: To be filled | F10: 2 | G10: =(COUNTIF(E10:E11,$F$411)+(COUNTIF(E10:E11,$F$410)*0.5))/(COUNTA(E10:E11)-COUNTIF(E10:E11,$F$412)) -> 0 | I10: 3 | J10: SR2.7
C11: T-ADI-DEP-2-2 | D11: The use of newly released (less than 60 days old) and outdated (more than 365 days old) OSS components is monitored and regulated. For example, an OSS firewall is configured to issue warnings (or block) when attempting to use OSS that was released or updated more than 365 days ago or less than 60 days ago. | E11: To be filled | I11: 3 | L11: OM-B-1 OM-B-2 SB-B-2
C12: T-ADI-DEP-3-1 | D12: An inventory of the dependencies in use is maintained. For example, an internal repository or knowledge base has been established for this purpose. | E12: To be filled | F12: 3 | G12: =(COUNTIF(E12:E14,$F$411)+(COUNTIF(E12:E14,$F$410)*0.5))/(COUNTA(E12:E14)-COUNTIF(E12:E14,$F$412)) -> 0 | I12: 4 | J12: SR1.5 | L12: SB-B-1
C13: T-ADI-DEP-3-2 | D13: When a Pull/Merge request is created, a list of all vulnerabilities in the dependencies used must be provided. This can be implemented by means of an SCA solution. | E13: To be filled | I13: 4
C14: T-ADI-DEP-3-3 | D14: Automatic updating of the dependencies in use is implemented. This can be achieved using specialized dependency update utilities. | E14: To be filled | I14: 4 | K14: 10
C15: T-ADI-DEP-4-1 | D15: Verification of the digital signature of the SBOM is performed prior to using dependencies in the build. The Verification of the SBOM digital signature is performed prior to using dependencies in the build. This can be implemented using an SCA | E15: To be filled | F15: 4 | G15: =(COUNTIF(E15:E16,$F$411)+(COUNTIF(E15:E16,$F$410)*0.5))/(COUNTA(E15:E16)-COUNTIF(E15:E16,$F$412)) -> 0 | I15: 6
C16: T-ADI-DEP-4-2 | D16: Required dependencies are built independently in a trusted environment. | E16: To be filled | I16: 6
B17: ='Assesment outcomes'!F4 -> Management and control of application development artifacts | C17: T-ADI-ART-0-1 | D17: Development artifact management is implemented in some form | E17: To be filled | F17: 0 | G17: =(COUNTIF(E17:E17,$F$406))/COUNTA(E17:E17) -> 0 | H17: =SUM(G18:G30)/4 -> 0 | I17: 0 | L17: SA-B-2
C18: T-ADI-ART-1-1 | D18: Artifact management is present in some form | E18: To be filled | F18: 1 | G18: =(COUNTIF(E18:E22,$F$411)+(COUNTIF(E18:E22,$F$410)*0.5))/(COUNTA(E18:E22)-COUNTIF(E18:E22,$F$412)) -> 0 | I18: 1
C19: T-ADI-ART-1-2 | D19: All development artifacts are stored in trusted registries. For example, an internal registry is used. | E19: To be filled | I19: 1 | K19: 60 58 57
C20: T-ADI-ART-1-3 | D20: External services are used for authentication in the registry. For example, integration with a LDAP/SAML system is in place, and local accounts are not used. | E20: To be filled | I20: 1 | K20: 60 59
C21: T-ADI-ART-1-4 | D21: Anonymous access to the registry is disabled | E21: To be filled | I21: 1
C22: T-ADI-ART-1-5 | D22: Auditing of all configuration changes to artifact repositories is configured and enabled | E22: To be filled | I22: 1 | K22: 108 106 101
C23: T-ADI-ART-2-1 | D23: Developers obtain artifacts for further work exclusively from internal repositories | E23: To be filled | F23: 2 | G23: =(COUNTIF(E23:E24,$F$411)+(COUNTIF(E23:E24,$F$410)*0.5))/(COUNTA(E23:E24)-COUNTIF(E23:E24,$F$412)) -> 0 | I23: 3
C24: T-ADI-ART-2-2 | D24: Webhooks use TLS version 1.2 or higher for interactions with the registry | E24: To be filled | I24: 3
C25: T-ADI-ART-3-1 | D25: An SBOM is created for all artifacts | E25: To be filled | F25: 3 | G25: =(COUNTIF(E25:E26,$F$411)+(COUNTIF(E25:E26,$F$410)*0.5))/(COUNTA(E25:E26)-COUNTIF(E25:E26,$F$412)) -> 0 | I25: 4 | J25: SR1.5 SE3.6 | K25: 4
C26: T-ADI-ART-3-2 | D26: Multi-factor authentication is used to access the registry. | E26: To be filled | I26: 4 | K26: 60 59
C27: T-ADI-ART-4-1 | D27: The build pipeline signs all artifacts it creates. | E27: To be filled | F27: 4 | G27: =(COUNTIF(E27:E30,$F$411)+(COUNTIF(E27:E30,$F$410)*0.5))/(COUNTA(E27:E30)) -> 0 | I27: 5 | J27: SE2.4
C28: T-ADI-ART-4-2 | D28: All artifacts in the registry are encrypted. | E28: To be filled | F28: 4 | I28: 5
C29: T-ADI-ART-4-3 | D29: Digital signatures are created for all artifacts after security checks have been completed and before they are uploaded to the trusted registry. | E29: To be filled | F29: 4 | I29: 5 | J29: SE2.4
C30: T-ADI-ART-4-4 | D30: Hash sums are generated for all artifacts before they are uploaded to the registry and verified during the build process. | E30: To be filled | F30: 4 | I30: 5
B32: Domain "Development environment security"
B33: ='Assesment outcomes'!F5 -> Developers workstations security | C33: T-DEV-COMP-0-1 | D33: Protective measures are applied to developer workstations. | E33: To be filled | F33: 0 | G33: =(COUNTIF(E33:E33,$F$406))/COUNTA(E33:E33) -> 0 | H33: =SUM(G34:G36)/2 -> 0 | I33: 0
C34: T-DEV-COMP-1-1 | D34: Baseline requirements for software and configurations on corporate developer workstations are approved and applied. For example, requirements for antivirus, operating system updates, and password policies. | E34: To be filled | F34: 1 | G34: =(COUNTIF(E34:E35,$F$411)+(COUNTIF(E34:E35,$F$410)*0.5))/(COUNTA(E34:E35)-COUNTIF(E34:E35,$F$412)) -> 0 | I34: 1
C35: T-DEV-COMP-1-2 | D35: Remote access to development tools from non-corporate (non-hardened) devices is permitted for only a small, limited number of devices. | E35: To be filled | I35: 1
C36: T-DEV-COMP-2-1 | D36: Remote access to development tools is only allowed either from corporate devices managed through MDM or via intermediary/proxy systems such as VDI or PAM. | E36: To be filled | F36: 2 | G36: =(COUNTIF(E36,$F$411)+(COUNTIF(E36,$F$410)*0.5))/COUNTA(E36) -> 0 | I36: 3
B37: ='Assesment outcomes'!F6 -> Secrets management in DEV/TEST environments | C37: T-DEV-SM-0-1 | D37: A secret-management practice exists in the organization | E37: To be filled | F37: 0 | G37: =(COUNTIF(E37:E37,$F$406))/COUNTA(E37:E37) -> 0 | H37: =SUM(G38:G44)/4 -> 0 | I37: 0 | K37: 7 | L37: SD-B-1
C38: T-DEV-SM-1-1 | D38: Secrets in the development environment are protected using the built-in mechanisms of development tools (e.g., CI/CD systems), without the use of dedicated secret management systems. | E38: To be filled | F38: 1 | G38: =(COUNTIF(E38:E39,$F$411)+(COUNTIF(E38:E39,$F$410)*0.5))/(COUNTA(E38:E39)-COUNTIF(E38:E39,$F$412)) -> 0 | I38: 1 | K38: 7 | L38: SD-B-1
C39: T-DEV-SM-1-2 | D39: Information security incidents related to the use of secrets in the development environment are handled by the Information Security team in cooperation with the developers. | E39: To be filled | I39: 1 | J39: CMVM1.1 | L39: IM-A-2
C40: T-DEV-SM-2-1 | D40: Secrets in the development environment are stored in a secret management tool, such as HashiCorp Vault. | E40: To be filled | F40: 2 | G40: =(COUNTIF(E40:E41,$F$411)+(COUNTIF(E40:E41,$F$410)*0.5))/(COUNTA(E40:E41)-COUNTIF(E40:E41,$F$412)) -> 0 | I40: 2 | K40: 7 | L40: SD-B-2
C41: T-DEV-SM-2-2 | D41: Developers and engineers exchange secrets using a secret management tool, such as HashiCorp Vault. | E41: To be filled | I41: 2 | L41: SD-B-2
...

Sheet DAF maturity pyramid
B2: DAF pyramid maturity Levels — Allocation of Practice Groups
B3: Practice ID | C3: Chaos | D3: Beginners | E3: Basic | F3: Enhanced | G3: Advanced | H3: Developed | I3: Expert | J3: Ultimate
B4: ='Assesment outcomes'!G3 -> T-ADI-DEP | C4: T-ADI-DEP-0 | E4: T-ADI-DEP-1 | F4: T-ADI-DEP-2 | G4: T-ADI-DEP-3 | I4: T-ADI-DEP-4
B5: ='Assesment outcomes'!G4 -> T-ADI-ART | C5: T-ADI-ART-0 | D5: T-ADI-ART-1 | F5: T-ADI-ART-2 | G5: T-ADI-ART-3 | H5: T-ADI-ART-4
B6: ='Assesment outcomes'!G5 -> T-DEV-COMP | C6: T-DEV-COMP-0 | D6: T-DEV-COMP-1 | F6: T-DEV-COMP-2
B7: ='Assesment outcomes'!G6 -> T-DEV-SM | C7: T-DEV-SM-0 | D7: T-DEV-SM-1 | E7: T-DEV-SM-2 | F7: T-DEV-SM-3 | I7: T-DEV-SM-4
B8: ='Assesment outcomes'!G7 -> T-DEV-BLD | C8: T-DEV-BLD-0 | E8: T-DEV-BLD-1 | F8: T-DEV-BLD-2 | H8: T-DEV-BLD-3 | I8: T-DEV-BLD-4
B9: ='Assesment outcomes'!G8 -> T-DEV-SCM | C9: T-DEV-SCM-0 | E9: T-DEV-SCM-1 | F9: T-DEV-SCM-2 | G9: T-DEV-SCM-3 | I9: T-DEV-SCM-4
B10: ='Assesment outcomes'!G9 -> T-DEV-SRC | C10: T-DEV-SRC-0 | D10: T-DEV-SRC-1 | F10: T-DEV-SRC-2 | G10: T-DEV-SRC-3 | I10: T-DEV-SRC-4
B11: ='Assesment outcomes'!G10 -> T-DEV-CICD | C11: T-DEV-CICD-0 | D11: T-DEV-CICD-1 | F11: T-DEV-CICD-2 | G11: T-DEV-CICD-3 | H11: T-DEV-CICD-4
B12: ='Assesment outcomes'!G11 -> T-CODE-SPC | C12: T-CODE-SPC-0 | E12: T-CODE-SPC-1 | G12: T-CODE-SPC-2 | H12: T-CODE-SPC-3 | J12: T-CODE-SPC-4
B13: ='Assesment outcomes'!G12 -> T-CODE-SST | C13: T-CODE-SST-0 | E13: T-CODE-SST-1 | F13: T-CODE-SST-2 | G13: T-CODE-SST-3 | J13: T-CODE-SST-4
B14: ='Assesment outcomes'!G13 -> T-CODE-SC | C14: T-CODE-SC-0 | D14: T-CODE-SC-1 | E14: T-CODE-SC-2 | G14: T-CODE-SC-3 | I14: T-CODE-SC-4
B15: ='Assesment outcomes'!G14 -> T-CODE-IMG | C15: T-CODE-IMG-0 | D15: T-CODE-IMG-1 | E15: T-CODE-IMG-2 | F15: T-CODE-IMG-3 | G15: T-CODE-IMG-4
B16: ='Assesment outcomes'!G15 -> T-CODE-SECDN | C16: T-CODE-SECDN-0 | D16: T-CODE-SECDN-1 | E16: T-CODE-SECDN-2 | F16: T-CODE-SECDN-3 | H16: T-CODE-SECDN-4
B17: ='Assesment outcomes'!G16 -> T-CODE-DOCKERFS | C17: T-CODE-DOCKERFS-0 | D17: T-CODE-DOCKERFS-1 | E17: T-CODE-DOCKERFS-2
B18: ='Assesment outcomes'!G17 -> T-PREPROD-DAST | C18: T-PREPROD-DAST-0 | F18: T-PREPROD-DAST-1 | G18: T-PREPROD-DAST-2 | H18: T-PREPROD-DAST-3 | I18: T-PREPROD-DAST-4
B19: ='Assesment outcomes'!G18 -> T-PREPROD-PENTEST | C19: T-PREPROD-PENTEST-0 | D19: T-PREPROD-PENTEST-1 | E19: T-PREPROD-PENTEST-2 | I19: T-PREPROD-PENTEST-4
B20: ='Assesment outcomes'!G21 -> T-PREPROD-VULN | C20: T-PREPROD-VULN-0 | E20: T-PREPROD-VULN-1 | G20: T-PREPROD-VULN-2 | H20: T-PREPROD-VULN-3 | J20: T-PREPROD-VULN-4
B21: ='Assesment outcomes'!G19 -> T-PREPROD-SECTEST | C21: T-PREPROD-SECTEST-0 | D21: T-PREPROD-SECTEST-1 | E21: T-PREPROD-SECTEST-2 | I21: T-PREPROD-SECTEST-3
B22: ='Assesment outcomes'!G20 -> T-PREPROD-MANSEC | C22: T-PREPROD-MANSEC-0 | E22: T-PREPROD-MANSEC-1 | F22: T-PREPROD-MANSEC-2
B23: ='Assesment outcomes'!G22 -> T-PROD-SM | C23: T-PROD-SM-0 | D23: T-PROD-SM-1 | E23: T-PROD-SM-2 | F23: T-PROD-SM-3 | H23: T-PROD-SM-4
B24: ='Assesment outcomes'!G23 -> T-PROD-DAST | C24: T-PROD-DAST-0 | G24: T-PROD-DAST-1 | H24: T-PROD-DAST-2 | I24: T-PROD-DAST-3 | J24: T-PROD-DAST-4
B25: ='Assesment outcomes'!G24 -> T-PROD-PENTEST | C25: T-PROD-PENTEST-0 | E25: T-PROD-PENTEST-1 | F25: T-PROD-PENTEST-2 | G25: T-PROD-PENTEST-3 | J25: T-PROD-PENTEST-4
B26: ='Assesment outcomes'!G25 -> T-PROD-ACCESS | C26: T-PROD-ACCESS-0 | D26: T-PROD-ACCESS-1 | F26: T-PROD-ACCESS-2 | G26: T-PROD-ACCESS-3 | J26: T-PROD-ACCESS-4
B27: ='Assesment outcomes'!G26 -> T-PROD-NETWORK | C27: T-PROD-NETWORK-0 | D27: T-PROD-NETWORK-1 | E27: T-PROD-NETWORK-2 | F27: T-PROD-NETWORK-3
B28: ='Assesment outcomes'!G27 -> T-PROD-RUN | C28: T-PROD-RUN-0 | E28: T-PROD-RUN-1 | F28: T-PROD-RUN-2 | H28: T-PROD-RUN-3
B29: ='Assesment outcomes'!G28 -> T-PROD-VULN | C29: T-PROD-VULN-0 | D29: T-PROD-VULN-1 | E29: T-PROD-VULN-2 | F29: T-PROD-VULN-3 | H29: T-PROD-VULN-4
B30: ='Assesment outcomes'!G29 -> T-PROD-EVENTS | C30: T-PROD-EVENTS-0 | E30: T-PROD-EVENTS-2 | F30: T-PROD-EVENTS-3
B31: ='Assesment outcomes'!G30 -> P-EDU-AWR | C31: P-EDU-AWR-0 | D31: P-EDU-AWR-1 | F31: P-EDU-AWR-2 | H31: P-EDU-AWR-3 | I31: P-EDU-AWR-4
B32: ='Assesment outcomes'!G31 -> P-EDU-KB | C32: P-EDU-KB-0 | D32: P-EDU-KB-1 | F32: P-EDU-KB-2 | G32: P-EDU-KB-3 | H32: P-EDU-KB-4
B33: ='Assesment outcomes'!G32 -> P-REQ-TM | C33: P-REQ-TM-0 | E33: P-REQ-TM-1 | F33: P-REQ-TM-2 | G33: P-REQ-TM-3 | H33: P-REQ-TM-4
B34: ='Assesment outcomes'!G33 -> P-REQ-RD | C34: P-REQ-RD-0 | D34: P-REQ-RD-1 | E34: P-REQ-RD-2 | G34: P-REQ-RD-3 | I34: P-REQ-RD-4
B35: ='Assesment outcomes'!G34 -> P-REQ-CR | C35: P-REQ-CR-0 | D35: P-REQ-CR-1 | E35: P-REQ-CR-2 | H35: P-REQ-CR-3 | I35: P-REQ-CR-4
B36: ='Assesment outcomes'!G35 -> P-REQ-STDR-App | C36: P-REQ-STDR-App-0 | F36: P-REQ-STDR-App-1 | G36: P-REQ-STDR-App-2 | H36: P-REQ-STDR-App-3 | I36: P-REQ-STDR-App-4
B37: ='Assesment outcomes'!G36 -> P-REQ-STDR-Infr | C37: P-REQ-STDR-Infr-0 | D37: P-REQ-STDR-Infr-1 | E37: P-REQ-STDR-Infr-2 | F37: P-REQ-STDR-Infr-3 | H37: P-REQ-STDR-Infr-4
B38: ='Assesment outcomes'!G37 -> P-DEFECT-MNG | C38: P-DEFECT-MNG-0 | D38: P-DEFECT-MNG-1 | E38: P-DEFECT-MNG-2 | F38: P-DEFECT-MNG-3 | J38: P-DEFECT-MNG-4
B39: ='Assesment outcomes'!G38 -> P-DEFECT-CNS | C39: P-DEFECT-CNS-0 | F39: P-DEFECT-CNS-1 | G39: P-DEFECT-CNS-2 | H39: P-DEFECT-CNS-3 | I39: P-DEFECT-CNS-4
B40: ='Assesment outcomes'!G39 -> P-MET-SET | C40: P-MET-SET-0 | F40: P-MET-SET-2 | G40: P-MET-SET-3
B41: ='Assesment outcomes'!G40 -> P-MET-EX | C41: P-MET-EX-0 | F41: P-MET-EX-2 | G41: P-MET-EX-3 | I41: P-MET-EX-4
...

Sheet SAMM_mapping
B1: SAMM subdomain | C1: SAMM maturity level | D1: SAMM requirements | E1: SAMM ID | F1: DAF practice ID | G1: DAF implementation status | H1: Comments | I1: count | K1: Total SAMM practices mapped to DAF | L1: Total requirments | M1: % of SAMM practices mapped to DAF
B2: Governance | K2: =COUNTA(G1:G235) -> 125 | L2: =COUNTA(I1:I235) -> 176 | M2: =(K2/L2)*100 -> 71.022727
B3: Strategy&Metrics
B4: Create and Promote | C4: 1 | D4: Do you understand the enterprise-wide risk appetite for your applications? | E4: SM-A-1 | F4: ='Practices and Requirements'!C315 -> P-REQ-TM-3-2 | G4: ='Practices and Requirements'!E315 -> To be filled | H4: ='Practices and Requirements'!V315 -> 0 | I4: 0
C5: 2 | D5: Do you have a strategic plan for application security and use it to make decisions? | E5: SM-A-2 | F5: ='Practices and Requirements'!C401 -> P-ROLE-RESP-2-4 | G5: ='Practices and Requirements'!E403 -> To be filled | H5: ='Practices and Requirements'!V403 -> 0 | I5: 0
C6: 3 | D6: Do you regularly review and update the Strategic Plan for Application Security? | E6: SM-A-3 | F6: ='Practices and Requirements'!C403 -> P-ROLE-RESP-3-2 | G6: ='Practices and Requirements'!E403 -> To be filled | H6: ='Practices and Requirements'!V404 -> 0 | I6: 0
B7: Measure and Improve | C7: 1 | D7: Do you use a set of metrics to measure the effectiveness and efficiency of the application security program across applications? | E7: SM-B-1 | F7: ='Practices and Requirements'!C370 -> P-MET-SET-2-1 | G7: ='Practices and Requirements'!E370 -> To be filled | H7: ='Practices and Requirements'!V370 -> 0 | I7: 0
C8: 2 | D8: Did you define Key Performance Indicators (KPI) from available application security metrics? | E8: SM-B-2 | F8: ='Practices and Requirements'!C371 -> P-MET-SET-2-2 | G8: ='Practices and Requirements'!E371 -> To be filled | H8: ='Practices and Requirements'!V371 -> 0 | I8: 0
C9: 3 | D9: Do you update the Application Security strategy and roadmap based on application security metrics and KPIs? | E9: SM-B-3 | F9: P-MET-SET-3-2 | G9: ='Practices and Requirements'!E373 -> To be filled | H9: ='Practices and Requirements'!V373 -> 0 | I9: 0
F10: ='Practices and Requirements'!C374 -> P-MET-EX-0-1 | G10: ='Practices and Requirements'!E374 -> To be filled | H10: ='Practices and Requirements'!V374 -> 0 | I10: 0
B11: Policy & Compliance | I11: 0
B12: Policy and Standards | C12: 1 | D12: Do you have and apply a common set of policies and standards throughout your organization? | E12: PC-A-1 | F12: ='Practices and Requirements'!C400 -> P-ROLE-RESP-2-3 | G12: ='Practices and Requirements'!E400 -> To be filled | H12: ='Practices and Requirements'!V400 -> 0 | I12: 0
C13: 2 | D13: Do you publish the organization's policies as test scripts or run-books for easy interpretation by development teams? | E13: PC-A-2 | F13: ='Practices and Requirements'!C195 -> T-PREPROD-SECTEST-2-1 | G13: ='Practices and Requirements'!E195 -> To be filled | H13: ='Practices and Requirements'!V195 -> 0 | I13: 0
C14: 3 | D14: Do you regularly report on policy and standard compliance, and use that information to guide compliance improvement efforts? | E14: PC-A-3 | F14: ='Practices and Requirements'!C279 -> T-PROD-VULN-4-1 | G14: ='Practices and Requirements'!E279 -> To be filled | H14: ='Practices and Requirements'!V279 -> 0 | I14: 0
B15: Compliance Management | C15: 1 | D15: Do you have a complete picture of your external compliance obligations? | E15: PC-B-1 | I15: 0
C16: 2 | D16: Do you have a standard set of security requirements and verification procedures addressing the organization's external compliance obligations? | E16: PC-B-2 | I16: 0
C17: 3 | D17: Do you regularly report on adherence to external compliance obligations and use that information to guide efforts to close compliance gaps? | E17: PC-B-3 | I17: 0
B18: Education & Guidance | I18: 0
B19: Training and Awareness | C19: 1 | D19: Do you require employees involved with application development to take SDLC training? | E19: EG-A-1 | F19: ='Practices and Requirements'!C286 -> P-EDU-AWR-0-1 | G19: ='Practices and Requirements'!E286 -> To be filled | H19: ='Practices and Requirements'!V286 -> 0 | I19: 0
F20: ='Practices and Requirements'!C287 -> P-EDU-AWR-1-1 | G20: ='Practices and Requirements'!E287 -> To be filled | H20: ='Practices and Requirements'!V287 -> 0 | I20: 0
C21: 2 | D21: Is training customized for individual roles such as developers, testers, or security champions? | E21: EG-A-2 | F21: ='Practices and Requirements'!C233 -> T-PROD-PENTEST-4-2 | G21: ='Practices and Requirements'!E233 -> To be filled | H21: ='Practices and Requirements'!V233 -> 0 | I21: 0
F22: ='Practices and Requirements'!C291 -> P-EDU-AWR-2-3 | G22: ='Practices and Requirements'!E291 -> To be filled | H22: ='Practices and Requirements'!V291 -> 0 | I22: 0
F23: ='Practices and Requirements'!C289 -> P-EDU-AWR-2-1 | G23: ='Practices and Requirements'!E289 -> To be filled | H23: ='Practices and Requirements'!V289 -> 0 | I23: 0
C24: 3 | D24: Have you implemented a Learning Management System or equivalent to track employee training and certification processes? | E24: EG-A-3 | F24: ='Practices and Requirements'!C289 -> P-EDU-AWR-2-1 | G24: ='Practices and Requirements'!E289 -> To be filled | H24: ='Practices and Requirements'!V289 -> 0 | I24: 0
F25: ='Practices and Requirements'!C292 -> P-EDU-AWR-2-4 | G25: ='Practices and Requirements'!E292 -> To be filled | H25: ='Practices and Requirements'!V292 -> 0 | I25: 0
B26: Organization and Culture | C26: 1 | D26: Have you identified a Security Champion for each development team? | E26: EG-B-1 | F26: ='Practices and Requirements'!C383 -> P-ROLE-SC-0-1 | G26: ='Practices and Requirements'!E383 -> To be filled | H26: ='Practices and Requirements'!V383 -> 0 | I26: 0
F27: ='Practices and Requirements'!C385 -> P-ROLE-SC-2-1 | G27: ='Practices and Requirements'!E385 -> To be filled | H27: ='Practices and Requirements'!V385 -> 0 | I27: 0
F28: ='Practices and Requirements'!C389 -> P-ROLE-SC-3-3 | G28: ='Practices and Requirements'!E389 -> To be filled | H28: ='Practices and Requirements'!V389 -> 0 | I28: 0
C29: 2 | D29: Does the organization have a Secure Software Center of Excellence (SSCE)? | E29: EG-B-2 | F29: ='Practices and Requirements'!C396 -> P-ROLE-RESP-1-1 | G29: ='Practices and Requirements'!E396 -> To be filled | H29: ='Practices and Requirements'!V396 -> 0 | I29: 0
C30: 3 | D30: Is there a centralized portal where developers and application security professionals from different teams and business units are able to communicate and share information? | E30: EG-B-3 | F30: ='Practices and Requirements'!C293 -> P-EDU-AWR-3-1 | G30: ='Practices and Requirements'!E293 -> To be filled | H30: ='Practices and Requirements'!V293 -> 0 | I30: 0
F31: ='Practices and Requirements'!C296 -> P-EDU-KB-0-1 | G31: ='Practices and Requirements'!E296 -> To be filled | H31: ='Practices and Requirements'!V296 -> 0 | I31: 0
B32: Design | I32: 0
B33: Threat Assessment | I33: 0
B34: Application Risk Profile | C34: 1 | D34: Do you classify applications according to business risk based on a simple and predefined set of questions? | E34: TA-A-1 | F34: ='Practices and Requirements'!C309 -> P-REQ-TM-1-2 | G34: ='Practices and Requirements'!E309 -> To be filled | H34: ='Practices and Requirements'!V309 -> 0 | I34: 0
F35: ='Practices and Requirements'!C310 -> P-REQ-TM-1-3 | G35: ='Practices and Requirements'!E310 -> To be filled | H35: ='Practices and Requirements'!V310 -> 0 | I35: 0
C36: 2 | D36: Do you use centralized and quantified application risk profiles to evaluate business risk? | E36: TA-A-2 | F36: ='Practices and Requirements'!C313 -> P-REQ-TM-2-3 | G36: ='Practices and Requirements'!E313 -> To be filled | H36: ='Practices and Requirements'!V313 -> 0 | I36: 0
C37: 3 | D37: Do you regularly review and update the risk profiles for your applications? | E37: TA-A-3 | I37: 0
B38: Threat Modeling | C38: 1 | D38: Do you identify and manage architectural design flaws with threat modeling? | E38: TA-B-1 | F38: ='Practices and Requirements'!C307 -> P-REQ-TM-0-1 | G38: ='Practices and Requirements'!E307 -> To be filled | H38: ='Practices and Requirements'!V307 -> 0 | I38: 0
C39: 2 | D39: Do you use a standard methodology, aligned with your application risk levels? | E39: TA-B-2 | F39: ='Practices and Requirements'!C315 -> P-REQ-TM-3-2 | G39: ='Practices and Requirements'!E315 -> To be filled | H39: ='Practices and Requirements'!V315 -> 0 | I39: 0
F40: ='Practices and Requirements'!C324 -> P-REQ-RD-3-1 | G40: ='Practices and Requirements'!E324 -> To be filled | H40: ='Practices and Requirements'!V324 -> 0 | I40: 0
...

Sheet DSOMM_mapping
B1: ID | C1: Dimension | D1: Sub Dimension | E1: Activity | F1: UUID | G1: DAF practice ID | H1: DAF implementation status | I1: Comments | J1: count | L1: Total DSOMM practices mapped to DAF | M1: Total requirments | N1: % of DSOMM practices mapped to DAF
B2: 1 | C2: Build and Deployment | D2: Build | E2: Building and testing of artifacts in virtual environments | F2: a340f46b-6360-4cb8-847b-a0d3483d09d3 | J2: 0 | L2: =COUNTA(I2:I257) -> 136 | M2: =COUNTA(B2:B257) -> 185 | N2: =(L2/M2)*100 -> 73.513514
B3: 2 | C3: Build and Deployment | D3: Build | E3: Pinning of artifacts | F3: f3c4971e-9f4d-4e59-8ed0-f0bdb6262477 | J3: 0
B4: 3 | C4: Build and Deployment | D4: Build | E4: Defined build process | F4: f6f7737f-25a9-4317-8de2-09bf59f29b5b | G4: ='Practices and Requirements'!C51 -> T-DEV-BLD-3-1 | H4: ='Practices and Requirements'!E51 -> To be filled | I4: ='Practices and Requirements'!V51 -> 0 | J4: 0
G5: ='Practices and Requirements'!C54 -> T-DEV-BLD-4-1 | H5: ='Practices and Requirements'!E54 -> To be filled | I5: ='Practices and Requirements'!V54 -> 0 | J5: 0
B6: 4 | C6: Build and Deployment | D6: Build | E6: SBOM of components | F6: 2858ac12-0179-40d9-9acf-1b839c030473 | G6: ='Practices and Requirements'!C4 -> T-ADI-DEP-0-1 | H6: ='Practices and Requirements'!E4 -> To be filled | I6: ='Practices and Requirements'!V4 -> 0 | J6: 0
G7: ='Practices and Requirements'!C25 -> T-ADI-ART-3-1 | H7: ='Practices and Requirements'!E25 -> To be filled | I7: ='Practices and Requirements'!V25 -> 0 | J7: 0
B8: 5 | C8: Build and Deployment | D8: Build | E8: Signing of artifacts | F8: 5786959d-0c6f-46a6-8e1c-a32ff1a50222 | J8: 0
J9: 0
B10: 6 | C10: Build and Deployment | D10: Build | E10: Signing of code | F10: 9f107927-61e9-4574-85ad-3f2b4bca8665 | J10: 0
B11: 7 | C11: Build and Deployment | D11: Deployment | E11: Environment depending configuration parameters (secrets) | F11: df428c9d-efa0-4226-9f47-a15bb53f822b | G11: ='Practices and Requirements'!C37 -> T-DEV-SM-0-1 | H11: ='Practices and Requirements'!E37 -> To be filled | I11: ='Practices and Requirements'!V37 -> 0 | J11: 0
G12: ='Practices and Requirements'!C38 -> T-DEV-SM-1-1 | H12: ='Practices and Requirements'!E38 -> To be filled | I12: ='Practices and Requirements'!V38 -> 0 | J12: 0
G13: ='Practices and Requirements'!C40 -> T-DEV-SM-2-1 | H13: ='Practices and Requirements'!E40 -> To be filled | I13: ='Practices and Requirements'!V40 -> 0 | J13: 0
G14: ='Practices and Requirements'!C216 -> T-PROD-SM-1-1 | H14: ='Practices and Requirements'!E216 -> To be filled | I14: ='Practices and Requirements'!V216 -> 0 | J14: 0
G15: ='Practices and Requirements'!C218 -> T-PROD-SM-2-1 | H15: ='Practices and Requirements'!E218 -> To be filled | I15: ='Practices and Requirements'!V218 -> 0 | J15: 0
G16: ='Practices and Requirements'!C42 -> T-DEV-SM-3-1 | H16: ='Practices and Requirements'!E42 -> To be filled | I16: ='Practices and Requirements'!V42 -> 0 | J16: 0
B17: 8 | C17: Build and Deployment | D17: Deployment | E17: Evaluation of the trust of used components | F17: 0de465a6-55a7-4343-af79-948bb5ff10ba | J17: 0
B18: 9 | C18: Build and Deployment | D18: Patch Management | E18: A patch policy is defined | F18: 99415139-6b50-441b-89e1-0aa59accd43d | G18: ='Practices and Requirements'!C6 -> T-ADI-DEP-1-2 | H18: ='Practices and Requirements'!E6 -> To be filled | I18: ='Practices and Requirements'!V6 -> 0 | J18: 0
G19: ='Practices and Requirements'!C271 -> T-PROD-VULN-1-2 | H19: ='Practices and Requirements'!E271 -> To be filled | I19: ='Practices and Requirements'!V271 -> 0 | J19: 0
G20: ='Practices and Requirements'!C200 -> T-PREPROD-VULN-1-2 | H20: ='Practices and Requirements'!E200 -> To be filled | I20: ='Practices and Requirements'!V200 -> 0 | J20: 0
B21: 10 | C21: Build and Deployment | D21: Patch Management | E21: Automated PRs for patches | F21: 8ae0b92c-10e0-4602-ba22-7524d6aed488 | G21: ='Practices and Requirements'!C14 -> T-ADI-DEP-3-3 | H21: ='Practices and Requirements'!E14 -> To be filled | I21: ='Practices and Requirements'!V14 -> 0 | J21: 0
B22: 11 | C22: Build and Deployment | D22: Deployment | E22: Rolling update on deployment | F22: 85d52588-f542-4225-a338-20dc22a5508d | J22: 0
B23: 12 | C23: Build and Deployment | D23: Patch Management | E23: Reduction of the attack surface | F23: 16e39c8f-5336-4001-88ed-a552d2447531 | J23: 0
B24: 13 | C24: Build and Deployment | D24: Deployment | E24: Handover of confidential parameters | F24: 94a96f79-8bd6-4904-97c0-994ff88f176a | J24: 0
B25: 14 | C25: Build and Deployment | D25: Patch Management | E25: Automated deployment of automated PRs | F25: 08f27c26-2c6a-47fe-9458-5e88f188085d | J25: 0
B26: 15 | C26: Build and Deployment | D26: Patch Management | E26: Automated merge of automated PRs | F26: f2594f8f-1cd6-45f9-af29-eaf3315698eb | J26: 0
B27: 16 | C27: Build and Deployment | D27: Patch Management | E27: Nightly build of images (base images) | F27: 34869eaf-f2e1-4926-b0bd-28c43402f057 | J27: 0
B28: 17 | C28: Build and Deployment | D28: Patch Management | E28: Usage of a maximum lifetime for images | F28: 485a3383-7f2e-4dba-bb84-479377070904 | J28: 0
B29: 18 | C29: Build and Deployment | D29: Patch Management | E29: Usage of a short maximum lifetime for images | F29: 6b96e5a0-ce34-4ea4-a88f-469d3b84546e | J29: 0
B30: 19 | C30: Build and Deployment | D30: Deployment | E30: Same artifact for environments | F30: a854b48d-83bd-4f8d-8621-a0bdd470837f | J30: 0
B31: 20 | C31: Build and Deployment | D31: Deployment | E31: Usage of feature toggles | F31: a511799b-045e-4b96-9843-7d63d8c1e2ad | J31: 0
B32: 21 | C32: Build and Deployment | D32: Deployment | E32: Blue/Green Deployment | F32: 0cb2626b-fb0d-4a0f-9688-57f787310d97 | J32: 0
B33: 22 | C33: Build and Deployment | D33: Deployment | E33: Defined deployment process | F33: 74938a3f-1269-49b9-9d0f-c43a79a1985a | J33: 0
... B37: 26 | C37: Build and Deployment | D37: Deployment | E37: Inventory of production dependencies | F37: 13e9757e-58e2-4277-bc0f-eadc674891e6 | J37: 0
B38: 27 | C38: Culture and Organization | D38: Design | E38: Conduction of simple threat modeling on technical level | F38: 47419324-e263-415b-815d-e7161b6b905e | G38: ='Practices and Requirements'!C307 -> P-REQ-TM-0-1 | H38: ='Practices and Requirements'!E307 -> To be filled | I38: ='Practices and Requirements'!V307 -> 0 | J38: 0
B39: 28 | C39: Culture and Organization | D39: Design | E39: Creation of advanced abuse stories | F39: 0a929c3e-ab9a-4206-8761-adf84b74622e | G39: ='Practices and Requirements'!C317 -> P-REQ-TM-4-1 | H39: ='Practices and Requirements'!E317 -> To be filled | I39: ='Practices and Requirements'!V317 -> 0 | J39: 0
B40: 29 | C40: Culture and Organization | D40: Design | E40: Creation of simple abuse stories | F40: bacf85b6-5bc0-405d-b5ba-a5d971467cc1 | G40: ='Practices and Requirements'!C317 -> P-REQ-TM-4-1 | H40: ='Practices and Requirements'!E317 -> To be filled | I40: ='Practices and Requirements'!V317 -> 0 | J40: 0
B41: 30 | C41: Culture and Organization | D41: Design | E41: Creation of threat modeling processes and standards | F41: dd5ed7c1-bdbf-400f-b75f-6d3953a1a04e | G41: ='Practices and Requirements'!C307 -> P-REQ-TM-0-1 | H41: ='Practices and Requirements'!E307 -> To be filled | I41: ='Practices and Requirements'!V307 -> 0 | J41: 0
G42: ='Practices and Requirements'!C315 -> P-REQ-TM-3-2 | H42: ='Practices and Requirements'!E315 -> To be filled | I42: ='Practices and Requirements'!V315 -> 0 | J42: 0
B43: 31 | C43: Culture and Organization | D43: Education and Guidance | E43: Conduction of collaborative security checks with developers and system administrators | F43: 95caef96-36ed-458c-a087-5c35d4f9dec2 | J43: 0
...

Sheet BSIMM14_mapping
B1: ID | C1: Activity | D1: DAF practice ID | E1: DAF implementation status | F1: Comments | G1: DAF count | H1: BSIMM count | J1: Total BSIMM14 practices mapped to DAF | K1: Total requirments | L1: % of BSIMM14 practices mapped to DAF
B2: GOVERNANCE | J2: =COUNTA(G2:G256) -> 62 | K2: =COUNTA(H2:H194) -> 126 | L2: =(J2/K2)*100 -> 49.206349
B3: Strategy & Metrics (SM)
B4: SM1.1 | C4: Publish process and evolve as necessary. | D4: ='Practices and Requirements'!$C$298 -> P-EDU-KB-2-1 | E4: ='Practices and Requirements'!E298 -> To be filled | F4: ='Practices and Requirements'!M298 -> 0 | G4: 0 | H4: 0
B5: SM1.3 | C5: Educate executives on software security. | H5: 0
B6: SM1.4 | C6: Implement security checkpoints and associated governance. | D6: ='Practices and Requirements'!C329 -> P-REQ-CR-1-1 | E6: ='Practices and Requirements'!E329 -> To be filled | F6: ='Practices and Requirements'!M329 -> 0 | G6: 0 | H6: 0
D7: ='Practices and Requirements'!C330 -> P-REQ-CR-2-1 | E7: ='Practices and Requirements'!E330 -> To be filled | F7: ='Practices and Requirements'!M330 -> 0
D8: ='Practices and Requirements'!C331 -> P-REQ-CR-3-1 | E8: ='Practices and Requirements'!E331 -> To be filled | F8: ='Practices and Requirements'!M331 -> 0
D9: ='Practices and Requirements'!C332 -> P-REQ-CR-4-1 | E9: ='Practices and Requirements'!E332 -> To be filled | F9: ='Practices and Requirements'!M332 -> 0
B10: SM2.1 | C10: Publish data about software security internally and use it to drive change. | D10: ='Practices and Requirements'!C379 -> P-MET-EX-3-3 | E10: ='Practices and Requirements'!E379 -> To be filled | F10: ='Practices and Requirements'!M379 -> 0 | G10: 0 | H10: 0
B11: SM2.2 | C11: Enforce security checkpoints and track exceptions. | D11: ='Practices and Requirements'!C331 -> P-REQ-CR-3-1 | E11: ='Practices and Requirements'!E331 -> To be filled | F11: ='Practices and Requirements'!M331 -> 0 | G11: 0 | H11: 0
D12: ='Practices and Requirements'!C357 -> P-DEFECT-MNG-3-3 | E12: ='Practices and Requirements'!E357 -> To be filled | F12: ='Practices and Requirements'!M357 -> 0
B13: SM2.3 | C13: Create or grow a satellite (security champions). | D13: ='Practices and Requirements'!C383 -> P-ROLE-SC-0-1 | E13: ='Practices and Requirements'!E383 -> To be filled | F13: ='Practices and Requirements'!M383 -> 0 | G13: 0 | H13: 0
B14: SM2.6 | C14: Require security sign-off prior to software release | H14: 0
B15: SM2.7 | C15: Create evangelism role and perform internal marketing. | H15: 0
B16: SM3.1 | C16: Use a software asset tracking application with portfolio view. | D16: ='Practices and Requirements'!C202 -> T-PREPROD-VULN-2-2 | E16: ='Practices and Requirements'!E202 -> To be filled | F16: ='Practices and Requirements'!M202 -> 0 | G16: 0 | H16: 0
D17: ='Practices and Requirements'!C273 -> T-PROD-VULN-2-2 | E17: ='Practices and Requirements'!E273 -> To be filled | F17: ='Practices and Requirements'!M273 -> 0
D18: ='Practices and Requirements'!C363 -> P-DEFECT-CNS-3-1 | E18: ='Practices and Requirements'!E363 -> To be filled | F18: ='Practices and Requirements'!M363 -> 0
D19: ='Practices and Requirements'!C364 -> P-DEFECT-CNS-3-2 | E19: ='Practices and Requirements'!E364 -> To be filled | F19: ='Practices and Requirements'!M364 -> 0
D20: ='Practices and Requirements'!C365 -> P-DEFECT-CNS-4-1 | E20: ='Practices and Requirements'!E365 -> To be filled | F20: ='Practices and Requirements'!M365 -> 0
B21: SM3.2 | C21: Make SSI efforts part of external marketing. | H21: 0
B22: SM3.3 | C22: Identify metrics and use them to drive resourcing. | D22: ='Practices and Requirements'!C370 -> P-MET-SET-2-1 | E22: ='Practices and Requirements'!E370 -> To be filled | F22: ='Practices and Requirements'!M370 -> 0 | G22: 0 | H22: 0
D23: ='Practices and Requirements'!C372 -> P-MET-SET-3-1 | E23: ='Practices and Requirements'!E372 -> To be filled | F23: ='Practices and Requirements'!M372 -> 0
D24: ='Practices and Requirements'!C375 -> P-MET-EX-2-1 | E24: ='Practices and Requirements'!E375 -> To be filled | F24: ='Practices and Requirements'!M375 -> 0
B25: SM3.4 | C25: Integrate software-defined lifecycle governance. | D25: ='Practices and Requirements'!C98 -> T-DEV-CICD-1-3 | E25: ='Practices and Requirements'!E98 -> To be filled | F25: ='Practices and Requirements'!M98 -> 0 | G25: 0 | H25: 0
D26: ='Practices and Requirements'!C125 -> T-CODE-SST-2-3 | E26: ='Practices and Requirements'!E125 -> To be filled | F26: ='Practices and Requirements'!M125 -> 0
D27: ='Practices and Requirements'!C138 -> T-CODE-SC-2-4 | E27: ='Practices and Requirements'!E138 -> To be filled | F27: ='Practices and Requirements'!M138 -> 0
D28: ='Practices and Requirements'!C149 -> T-CODE-IMG-2-1 | E28: ='Practices and Requirements'!E149 -> To be filled | F28: ='Practices and Requirements'!M149 -> 0
D29: ='Practices and Requirements'!C354 -> P-DEFECT-MNG-2-2 | E29: ='Practices and Requirements'!E354 -> To be filled | F29: ='Practices and Requirements'!M354 -> 0
B30: SM3.5 | C30: Integrate software supply chain risk management. | D30: ='Practices and Requirements'!C131 -> T-CODE-SC-0-1 | E30: ='Practices and Requirements'!E131 -> To be filled | F30: ='Practices and Requirements'!M131 -> 0 | G30: 0 | H30: 0
B31: Compliance & Policy (CP)
B32: CP1.1 | C32: Unify regulatory pressures. | H32: 0
B33: CP1.2 | C33: Identify privacy obligations. | H33: 0
B34: CP1.3 | C34: Create policy. | H34: 0
B35: CP2.1 | C35: Build a PII inventry. | H35: 0
B36: CP2.2 | C36: Require security sign-off for compliance-related risk. | H36: 0
B37: CP2.3 | C37: Implement and track controls for compliance. | D37: ='Practices and Requirements'!C328 -> P-REQ-CR-0-1 | E37: ='Practices and Requirements'!E328 -> To be filled | F37: ='Practices and Requirements'!M328 -> 0 | G37: 0 | H37: 0
D38: ='Practices and Requirements'!C329 -> P-REQ-CR-1-1 | E38: ='Practices and Requirements'!E329 -> To be filled | F38: ='Practices and Requirements'!M329 -> 0
D39: ='Practices and Requirements'!C330 -> P-REQ-CR-2-1 | E39: ='Practices and Requirements'!E330 -> To be filled | F39: ='Practices and Requirements'!M330 -> 0
B40: CP2.4 | C40: Include software security SLAs in all vendor contracts. | H40: 0
...
